Workbook
Name Business​: Intelligence!#REF!
Name Business​: 'Intelligence OLD'!$AC$9:$AC$15
Name Business​: '4. VAS list'!$AL$8:$AL$14
Name DigitalAccessAndProtection: Intelligence!#REF!
Name DigitalAccessAndProtection: 'Intelligence OLD'!$Z$10:$Z$15
Name DigitalAccessAndProtection: '4. VAS list'!$AI$9:$AI$14
Name DigitalAccessAndProtection​: Intelligence!#REF!
Name DigitalAccessAndProtection​: 'Intelligence OLD'!$AB$9:$AB$14
Name DigitalAccessAndProtection​: '4. VAS list'!$AK$8:$AK$13
Name Financial​: Intelligence!#REF!
Name Financial​: 'Intelligence OLD'!$Y$9:$Y$11
Name Financial​: '4. VAS list'!$AH$8:$AH$10
Name Health: Intelligence!#REF!
Name Health: 'Intelligence OLD'!$U$10:$U$22
Name Health: '4. VAS list'!$AD$9:$AD$24
Name Health​: Intelligence!#REF!
Name Health​: 'Intelligence OLD'!$W$9:$W$22
Name Health​: '4. VAS list'!$AF$8:$AF$23
Name HomeAndFamily: Intelligence!#REF!
Name HomeAndFamily: 'Intelligence OLD'!$Y$10:$Y$16
Name HomeAndFamily: '4. VAS list'!$AH$9:$AH$16
Name HomeAndFamily​: Intelligence!#REF!
Name HomeAndFamily​: 'Intelligence OLD'!$AA$9:$AA$15
Name HomeAndFamily​: '4. VAS list'!$AJ$8:$AJ$14
Name LOB: Intelligence!#REF!
Name LOB: 'Intelligence OLD'!$V$9:$V$15
Name LOB: '4. VAS list'!$AE$8:$AE$14
Name Mobility​: Intelligence!#REF!
Name Mobility​: 'Intelligence OLD'!$Z$9:$Z$15
Name Mobility​: '4. VAS list'!$AI$8:$AI$14
Name Protection​: Intelligence!#REF!
Name Protection​: 'Intelligence OLD'!$X$9:$X$11
Name Protection​: '4. VAS list'!$AG$8:$AG$10
Name VasNAme: REPOSITORY!$A$3:$A$35

Sheet Home
J4: 🔍 View the pipeline (outputs)
C6: VALUE TREE | J6: 00 VAS comparison | M6: 02 VAS deep dive | P6: 03 Master Scoring
J7: Compare VAS lists between themselves | M7: Sumup of VAS data and next step suggestions | P7: Compare VAS against key criteria
C9: GENERALI VAS
J10: Explore > | M10: Explore > | P10: Explore >
C11: WHY IT EXISTS
C12: To create total clarity, consistency and visibility over the methodology we are using. | J12: 📊 Score the pipeline (inputs)
J14: 04 VAS list | M14: 04 Scoring sheets | P14: 05 Input GTM Strategy
J15: Add VAS that will be involved into analysis | M15: Score VAS individually, so that an average can be taken | P15: Add currently strategy of VAS
J17: Explore > | M17: Explore > | P17: Explore >
J19: 🧑‍🎓 Scoring guide (instructions)
J21: 06 Tool manual | M21: 07 Scoring criteria
J22: Step by step instructions on how to use this VAS prioritisation tool | M22: Find a breakdown of all the scoring criteria and weighting used to assess VAS
J24: Explore >

Sheet REPOSITORY
A2: VasNAme | B2: Description | C2: LOB | D2: Category | E2: Priority1 | F2: Priority2 | G2: Priority3 | H2: Priorirty4 | I2: Bundle/Unbundle | J2: PriceVisibility | K2: Direct/Tiered | L2: Digital/Physiscal | M2: Paid_Media | N2: Paid _Channel | O2: Organic Media | P2: Organic_Channel? | Q2: Owned_Media | R2: Owned_Channel | S2: Importance_ competitive | T2: Competitor_differentiation | U2: Profiled_Target | V2: Core_Business_Sales | W2: %Multiproduct | X2: Customer_base | Y2: Customer_acquisition_costs | Z2: Claim_costs | AA2: TOTAL_GrowCoreBusiness | AB2: Business_Risk | AC2: TOTAL_Business_Risk | AD2: Perceived_Value | AE2: Potential_Reach | AF2: TOTAL_Percived_Value | AG2: Improve_NPS | AH2: Retention | AI2: Customer_interactions | AJ2: Differentiation | AK2: Regulation | AL2: TOTAL_Execution
A3: =IF('4. VAS list'!B8="","",'4. VAS list'!B8) -> Telemedicine | B3: ='4. VAS list'!C8 -> Cover the costs of private healthcare, from diagnosis to treatment | C3: ='4. VAS list'!G8 -> DigitalAccessAndProtection​ | D3: ='4. VAS list'!H8 -> Practical guides / Prevention information​ | E3: ='4. VAS list'!I8 -> Core Business | F3: ='4. VAS list'!G8 -> DigitalAccessAndProtection​ | G3: ='4. VAS list'!H8 -> Practical guides / Prevention information​ | H3: ='4. VAS list'!I8 -> Core Business | I3: ='5. Input GTM Strategy '!E13 -> Bundle | J3: ='5. Input GTM Strategy '!F13 -> Hidden | K3: ='5. Input GTM Strategy '!H13 -> Third parties | L3: ='5. Input GTM Strategy '!I13 -> Physical | M3: ='5. Input GTM Strategy '!H13 -> Third parties | N3: ='5. Input GTM Strategy '!I13 -> Physical | O3: ='5. Input GTM Strategy '!K13 -> 2 | P3: ='5. Input GTM Strategy '!L13 -> Radio | Q3: ='5. Input GTM Strategy '!M13 -> 2 | R3: ='5. Input GTM Strategy '!N13 -> Social Media | S3: ='5. Input GTM Strategy '!R13 -> Medium Importance | T3: ='5. Input GTM Strategy '!S13 -> 0 | U3: ='5. Input GTM Strategy '!U13 -> High profilation | V3: ='1. Master scoring '!R14 -> 5 | W3: ='1. Master scoring '!S14 | X3: ='1. Master scoring '!T14 -> 4 | Y3: ='1. Master scoring '!U14 -> 5 | Z3: ='1. Master scoring '!V14 -> 2.3333333 | AA3: ='1. Master scoring '!W14 -> 1.0208333 | AB3: ='1. Master scoring '!X14 -> 4.3333333 | AC3: ='1. Master scoring '!Y14 -> 4.3333333 | ... AI3: ='1. Master scoring '!AE14 -> 5 | AJ3: ='1. Master scoring '!#REF! -> #REF! | AK3: ='1. Master scoring '!AF14 -> 5 | AL3: ='1. Master scoring '!AG14 -> 2.5
A4: =IF('4. VAS list'!B9="","",'4. VAS list'!B9) -> ID Theft | B4: ='4. VAS list'!C9 -> Cover the costs you might incur from being defrauded | C4: ='4. VAS list'!G9 -> Health​ | D4: ='4. VAS list'!H9 -> Medical & health specialist services​ | E4: ='4. VAS list'!I9 -> Core Business | F4: ='4. VAS list'!G9 -> Health​ | G4: ='4. VAS list'!H9 -> Medical & health specialist services​ | H4: ='4. VAS list'!I9 -> Core Business | I4: ='5. Input GTM Strategy '!E14 -> Standalone | J4: ='5. Input GTM Strategy '!F14 -> Visible | K4: ='5. Input GTM Strategy '!H14 -> Third parties | L4: ='5. Input GTM Strategy '!I14 -> Phygital | M4: ='5. Input GTM Strategy '!H14 -> Third parties | N4: ='5. Input GTM Strategy '!I14 -> Phygital | O4: ='5. Input GTM Strategy '!K14 -> 3 or more | P4: ='5. Input GTM Strategy '!L14 -> TV | Q4: ='5. Input GTM Strategy '!M14 -> 1 | R4: ='5. Input GTM Strategy '!N14 -> Web marketing | S4: ='5. Input GTM Strategy '!R14 -> High Importance | T4: ='5. Input GTM Strategy '!S14 -> 0 | U4: ='5. Input GTM Strategy '!U14 -> Medium Profilation | V4: ='1. Master scoring '!R15 -> 5 | W4: ='1. Master scoring '!S15 | X4: ='1. Master scoring '!T15 -> 2 | Y4: ='1. Master scoring '!U15 -> 5 | Z4: ='1. Master scoring '!V15 -> 2.3333333 | AA4: ='1. Master scoring '!W15 -> 0.89583333 | AB4: ='1. Master scoring '!X15 -> 4 | AC4: ='1. Master scoring '!Y15 -> 4 | ... AI4: ='1. Master scoring '!AE15 -> 5 | AJ4: ='1. Master scoring '!#REF! -> #REF! | AK4: ='1. Master scoring '!AF15 -> 4.3333333 | AL4: ='1. Master scoring '!AG15 -> 2.4166667
A5: =IF('4. VAS list'!B10="","",'4. VAS list'!B10) -> Vehicle Geolocation | B5: ='4. VAS list'!C10 -> Install an approved GPS tracking device and reduce vehicle insurance premium | C5: ='4. VAS list'!G10 -> Mobility​ | D5: ='4. VAS list'!H10 -> Mobility assistance (bikes, fines help)​ | E5: ='4. VAS list'!I10 -> Core Business | F5: ='4. VAS list'!G10 -> Mobility​ | G5: ='4. VAS list'!H10 -> Mobility assistance (bikes, fines help)​ | H5: ='4. VAS list'!I10 -> Core Business | I5: ='5. Input GTM Strategy '!E15 -> Standalone | J5: ='5. Input GTM Strategy '!F15 -> Hidden | K5: ='5. Input GTM Strategy '!H15 -> Tiered Network | L5: ='5. Input GTM Strategy '!I15 -> Physical | M5: ='5. Input GTM Strategy '!H15 -> Tiered Network | N5: ='5. Input GTM Strategy '!I15 -> Physical | O5: ='5. Input GTM Strategy '!K15 -> 1 | P5: ='5. Input GTM Strategy '!L15 -> Print media | Q5: ='5. Input GTM Strategy '!M15 -> 3 or more | R5: ='5. Input GTM Strategy '!N15 -> Social Media | S5: ='5. Input GTM Strategy '!R15 -> High Importance | T5: ='5. Input GTM Strategy '!S15 -> 0 | U5: ='5. Input GTM Strategy '!U15 -> High profilation | V5: ='1. Master scoring '!R16 -> 5 | W5: ='1. Master scoring '!S16 | X5: ='1. Master scoring '!T16 -> 2.6666667 | Y5: ='1. Master scoring '!U16 -> 4.3333333 | Z5: ='1. Master scoring '!V16 -> 3 | AA5: ='1. Master scoring '!W16 -> 0.9375 | AB5: ='1. Master scoring '!X16 -> 3.6666667 | AC5: ='1. Master scoring '!Y16 -> 3.6666667 | ... AI5: ='1. Master scoring '!AE16 -> 4.6666667 | AJ5: ='1. Master scoring '!#REF! -> #REF! | AK5: ='1. Master scoring '!AF16 -> 5 | AL5: ='1. Master scoring '!AG16 -> 2.2916667
A6: =IF('4. VAS list'!B11="","",'4. VAS list'!B11) -> Pet Care | B6: ='4. VAS list'!C11 -> Cover the cost of veterinary fees for illnesses or injuries | C6: ='4. VAS list'!G11 -> HomeAndFamily​ | D6: ='4. VAS list'!H11 -> Pet care​ | E6: ='4. VAS list'!I11 -> Core Business | F6: ='4. VAS list'!G11 -> HomeAndFamily​ | G6: ='4. VAS list'!H11 -> Pet care​ | H6: ='4. VAS list'!I11 -> Core Business | I6: ='5. Input GTM Strategy '!E16 -> Bundle | J6: ='5. Input GTM Strategy '!F16 -> Visible | K6: ='5. Input GTM Strategy '!H16 -> Tiered Network | L6: ='5. Input GTM Strategy '!I16 -> Digital | M6: ='5. Input GTM Strategy '!H16 -> Tiered Network | N6: ='5. Input GTM Strategy '!I16 -> Digital | O6: ='5. Input GTM Strategy '!K16 -> 3 or more | P6: ='5. Input GTM Strategy '!L16 -> Display | Q6: ='5. Input GTM Strategy '!M16 -> 1 | R6: ='5. Input GTM Strategy '!N16 -> Events | S6: ='5. Input GTM Strategy '!R16 -> Low Importance | T6: ='5. Input GTM Strategy '!S16 -> 0 | U6: ='5. Input GTM Strategy '!U16 -> Low Profilation | V6: ='1. Master scoring '!R17 -> 4.6666667 | W6: ='1. Master scoring '!S17 | X6: ='1. Master scoring '!T17 -> 2.3333333 | Y6: ='1. Master scoring '!U17 -> 4.3333333 | Z6: ='1. Master scoring '!V17 -> 3 | AA6: ='1. Master scoring '!W17 -> 0.89583333 | AB6: ='1. Master scoring '!X17 -> 3.3333333 | AC6: ='1. Master scoring '!Y17 -> 3.3333333 | ... AI6: ='1. Master scoring '!AE17 -> 4.6666667 | AJ6: ='1. Master scoring '!#REF! -> #REF! | AK6: ='1. Master scoring '!AF17 -> 4.3333333 | AL6: ='1. Master scoring '!AG17 -> 2.375
A7: =IF('4. VAS list'!B12="","",'4. VAS list'!B12) -> Road Assistance | B7: ='4. VAS list'!C12 -> Lorem ipsum | C7: ='4. VAS list'!G12 -> Mobility​ | D7: ='4. VAS list'!H12 -> Emergency response​ | E7: ='4. VAS list'!I12 -> Core Business | F7: ='4. VAS list'!G12 -> Mobility​ | G7: ='4. VAS list'!H12 -> Emergency response​ | H7: ='4. VAS list'!I12 -> Core Business | I7: ='5. Input GTM Strategy '!E17 -> Pack | J7: ='5. Input GTM Strategy '!F17 -> Hidden | K7: ='5. Input GTM Strategy '!H17 -> Both | L7: ='5. Input GTM Strategy '!I17 -> Digital | M7: ='5. Input GTM Strategy '!H17 -> Both | N7: ='5. Input GTM Strategy '!I17 -> Digital | O7: ='5. Input GTM Strategy '!K17 -> 1 | P7: ='5. Input GTM Strategy '!L17 -> TV | Q7: ='5. Input GTM Strategy '!M17 -> 3 or more | R7: ='5. Input GTM Strategy '!N17 -> Events | S7: ='5. Input GTM Strategy '!R17 -> Low Importance | T7: ='5. Input GTM Strategy '!S17 -> 0 | U7: ='5. Input GTM Strategy '!U17 -> Low Profilation | V7: ='1. Master scoring '!R18 -> 4 | W7: ='1. Master scoring '!S18 | X7: ='1. Master scoring '!T18 -> 2.6666667 | Y7: ='1. Master scoring '!U18 -> 3.6666667 | Z7: ='1. Master scoring '!V18 -> 3.6666667 | AA7: ='1. Master scoring '!W18 -> 0.875 | AB7: ='1. Master scoring '!X18 -> 3.6666667 | AC7: ='1. Master scoring '!Y18 -> 3.6666667 | ... AI7: ='1. Master scoring '!AE18 -> 4.3333333 | AJ7: ='1. Master scoring '!#REF! -> #REF! | AK7: ='1. Master scoring '!AF18 -> 3.3333333 | AL7: ='1. Master scoring '!AG18 -> 1.875
A8: =IF('4. VAS list'!B13="","",'4. VAS list'!B13) | B8: ='4. VAS list'!C13 -> 0 | C8: ='4. VAS list'!G13 -> 0 | D8: ='4. VAS list'!H13 -> 0 | E8: ='4. VAS list'!I13 -> 0 | F8: ='4. VAS list'!G13 -> 0 | G8: ='4. VAS list'!H13 -> 0 | H8: ='4. VAS list'!I13 -> 0 | I8: ='5. Input GTM Strategy '!E18 -> Bundle | J8: ='5. Input GTM Strategy '!F18 -> Visible | K8: ='5. Input GTM Strategy '!H18 -> Both | L8: ='5. Input GTM Strategy '!I18 -> Physical | M8: ='5. Input GTM Strategy '!H18 -> Both | N8: ='5. Input GTM Strategy '!I18 -> Physical | O8: ='5. Input GTM Strategy '!K18 -> 2 | P8: ='5. Input GTM Strategy '!L18 -> Print media | Q8: ='5. Input GTM Strategy '!M18 -> 1 | R8: ='5. Input GTM Strategy '!N18 -> Web marketing | S8: ='5. Input GTM Strategy '!R18 -> Medium Importance | T8: ='5. Input GTM Strategy '!S18 -> 0 | U8: ='5. Input GTM Strategy '!U18 -> Mass Market | V8: ='1. Master scoring '!R19 | W8: ='1. Master scoring '!S19 | X8: ='1. Master scoring '!T19 | Y8: ='1. Master scoring '!U19 | Z8: ='1. Master scoring '!V19 | AA8: ='1. Master scoring '!W19 | AB8: ='1. Master scoring '!X19 | AC8: ='1. Master scoring '!Y19 | ... AI8: ='1. Master scoring '!AE19 | AJ8: ='1. Master scoring '!#REF! -> #REF! | AK8: ='1. Master scoring '!AF19 | AL8: ='1. Master scoring '!AG19
A9: =IF('4. VAS list'!B14="","",'4. VAS list'!B14) | B9: ='4. VAS list'!C14 -> 0 | C9: ='4. VAS list'!G14 -> 0 | D9: ='4. VAS list'!H14 -> 0 | E9: ='4. VAS list'!I14 -> 0 | F9: ='4. VAS list'!G14 -> 0 | G9: ='4. VAS list'!H14 -> 0 | H9: ='4. VAS list'!I14 -> 0 | I9: ='5. Input GTM Strategy '!E19 -> 0 | J9: ='5. Input GTM Strategy '!F19 -> 0 | K9: ='5. Input GTM Strategy '!H19 -> 0 | L9: ='5. Input GTM Strategy '!I19 -> 0 | M9: ='5. Input GTM Strategy '!H19 -> 0 | N9: ='5. Input GTM Strategy '!I19 -> 0 | O9: ='5. Input GTM Strategy '!K19 -> 0 | P9: ='5. Input GTM Strategy '!L19 -> 0 | Q9: ='5. Input GTM Strategy '!M19 -> 0 | R9: ='5. Input GTM Strategy '!N19 -> 0 | S9: ='5. Input GTM Strategy '!R19 -> 0 | T9: ='5. Input GTM Strategy '!S19 -> 0 | U9: ='5. Input GTM Strategy '!U19 -> 0 | V9: ='1. Master scoring '!R20 | W9: ='1. Master scoring '!S20 | X9: ='1. Master scoring '!T20 -> 0 | Y9: ='1. Master scoring '!U20 -> 0 | Z9: ='1. Master scoring '!V20 -> 0 | AA9: ='1. Master scoring '!W20 | AB9: ='1. Master scoring '!X20 | AC9: ='1. Master scoring '!Y20 | ... AI9: ='1. Master scoring '!AE20 -> 0 | AJ9: ='1. Master scoring '!#REF! -> #REF! | AK9: ='1. Master scoring '!AF20 | AL9: ='1. Master scoring '!AG20
A10: =IF('4. VAS list'!B15="","",'4. VAS list'!B15) | B10: ='4. VAS list'!C15 -> 0 | C10: ='4. VAS list'!G15 -> 0 | D10: ='4. VAS list'!H15 -> 0 | E10: ='4. VAS list'!I15 -> 0 | F10: ='4. VAS list'!G15 -> 0 | G10: ='4. VAS list'!H15 -> 0 | H10: ='4. VAS list'!I15 -> 0 | I10: ='5. Input GTM Strategy '!E20 -> 0 | J10: ='5. Input GTM Strategy '!F20 -> 0 | K10: ='5. Input GTM Strategy '!H20 -> 0 | L10: ='5. Input GTM Strategy '!I20 -> 0 | M10: ='5. Input GTM Strategy '!H20 -> 0 | N10: ='5. Input GTM Strategy '!I20 -> 0 | O10: ='5. Input GTM Strategy '!K20 -> 0 | P10: ='5. Input GTM Strategy '!L20 -> 0 | Q10: ='5. Input GTM Strategy '!M20 -> 0 | R10: ='5. Input GTM Strategy '!N20 -> 0 | S10: ='5. Input GTM Strategy '!R20 -> 0 | T10: ='5. Input GTM Strategy '!S20 -> 0 | U10: ='5. Input GTM Strategy '!U20 -> 0 | V10: ='1. Master scoring '!R21 | W10: ='1. Master scoring '!S21 | X10: ='1. Master scoring '!T21 -> 0 | Y10: ='1. Master scoring '!U21 -> 0 | Z10: ='1. Master scoring '!V21 -> 0 | AA10: ='1. Master scoring '!W21 | AB10: ='1. Master scoring '!X21 | AC10: ='1. Master scoring '!Y21 | ... AI10: ='1. Master scoring '!AE21 -> 0 | AJ10: ='1. Master scoring '!#REF! -> #REF! | AK10: ='1. Master scoring '!AF21 | AL10: ='1. Master scoring '!AG21
A11: =IF('4. VAS list'!B16="","",'4. VAS list'!B16) | B11: ='4. VAS list'!C16 -> 0 | C11: ='4. VAS list'!G16 -> 0 | D11: ='4. VAS list'!H16 -> 0 | E11: ='4. VAS list'!F16 -> 0 | F11: ='4. VAS list'!G16 -> 0 | G11: ='4. VAS list'!H16 -> 0 | H11: ='4. VAS list'!I16 -> 0 | I11: ='5. Input GTM Strategy '!E21 -> 0 | J11: ='5. Input GTM Strategy '!F21 -> 0 | K11: ='5. Input GTM Strategy '!H21 -> 0 | L11: ='5. Input GTM Strategy '!I21 -> 0 | M11: ='5. Input GTM Strategy '!H21 -> 0 | N11: ='5. Input GTM Strategy '!I21 -> 0 | O11: ='5. Input GTM Strategy '!K21 -> 0 | P11: ='5. Input GTM Strategy '!L21 -> 0 | Q11: ='5. Input GTM Strategy '!M21 -> 0 | R11: ='5. Input GTM Strategy '!N21 -> 0 | S11: ='5. Input GTM Strategy '!R21 -> 0 | T11: ='5. Input GTM Strategy '!S21 -> 0 | U11: ='5. Input GTM Strategy '!U21 -> 0 | V11: ='1. Master scoring '!R22 | W11: ='1. Master scoring '!S22 | X11: ='1. Master scoring '!T22 -> 0 | Y11: ='1. Master scoring '!U22 -> 0 | Z11: ='1. Master scoring '!V22 -> 0 | AA11: ='1. Master scoring '!W22 | AB11: ='1. Master scoring '!X22 | AC11: ='1. Master scoring '!Y22 | ... AI11: ='1. Master scoring '!AE22 -> 0 | AJ11: ='1. Master scoring '!#REF! -> #REF! | AK11: ='1. Master scoring '!AF22 | AL11: ='1. Master scoring '!AG22
A12: =IF('4. VAS list'!B17="","",'4. VAS list'!B17) | B12: ='4. VAS list'!C17 -> 0 | C12: ='4. VAS list'!G17 -> 0 | D12: ='4. VAS list'!H17 -> 0 | E12: ='4. VAS list'!F17 -> 0 | F12: ='4. VAS list'!G17 -> 0 | G12: ='4. VAS list'!H17 -> 0 | H12: ='4. VAS list'!I17 -> 0 | I12: ='5. Input GTM Strategy '!E22 -> 0 | J12: ='5. Input GTM Strategy '!F22 -> 0 | K12: ='5. Input GTM Strategy '!H22 -> 0 | L12: ='5. Input GTM Strategy '!I22 -> 0 | M12: ='5. Input GTM Strategy '!H22 -> 0 | N12: ='5. Input GTM Strategy '!I22 -> 0 | O12: ='5. Input GTM Strategy '!K22 -> 0 | P12: ='5. Input GTM Strategy '!L22 -> 0 | Q12: ='5. Input GTM Strategy '!M22 -> 0 | R12: ='5. Input GTM Strategy '!N22 -> 0 | S12: ='5. Input GTM Strategy '!R22 -> 0 | T12: ='5. Input GTM Strategy '!S22 -> 0 | U12: ='5. Input GTM Strategy '!U22 -> 0 | V12: ='1. Master scoring '!R23 | W12: ='1. Master scoring '!S23 | X12: ='1. Master scoring '!T23 -> 0 | Y12: ='1. Master scoring '!U23 -> 0 | Z12: ='1. Master scoring '!V23 -> 0 | AA12: ='1. Master scoring '!W23 | AB12: ='1. Master scoring '!X23 | AC12: ='1. Master scoring '!Y23 | ... AI12: ='1. Master scoring '!AE23 -> 0 | AJ12: ='1. Master scoring '!#REF! -> #REF! | AK12: ='1. Master scoring '!AF23 | AL12: ='1. Master scoring '!AG23
A13: =IF('4. VAS list'!B18="","",'4. VAS list'!B18) | B13: ='4. VAS list'!C18 -> 0 | C13: ='4. VAS list'!G18 -> 0 | D13: ='4. VAS list'!E18 -> 0 | E13: ='4. VAS list'!F18 -> 0 | F13: ='4. VAS list'!G18 -> 0 | G13: ='4. VAS list'!H18 -> 0 | H13: ='4. VAS list'!I18 -> 0 | I13: ='5. Input GTM Strategy '!E23 -> 0 | J13: ='5. Input GTM Strategy '!F23 -> 0 | K13: ='5. Input GTM Strategy '!H23 -> 0 | L13: ='5. Input GTM Strategy '!I23 -> 0 | M13: ='5. Input GTM Strategy '!H23 -> 0 | N13: ='5. Input GTM Strategy '!I23 -> 0 | O13: ='5. Input GTM Strategy '!K23 -> 0 | P13: ='5. Input GTM Strategy '!L23 -> 0 | Q13: ='5. Input GTM Strategy '!M23 -> 0 | R13: ='5. Input GTM Strategy '!N23 -> 0 | S13: ='5. Input GTM Strategy '!R23 -> 0 | T13: ='5. Input GTM Strategy '!S23 -> 0 | U13: ='5. Input GTM Strategy '!U23 -> 0 | V13: ='1. Master scoring '!R24 | W13: ='1. Master scoring '!S24 | X13: ='1. Master scoring '!T24 -> 0 | Y13: ='1. Master scoring '!U24 -> 0 | Z13: ='1. Master scoring '!V24 -> 0 | AA13: ='1. Master scoring '!W24 | AB13: ='1. Master scoring '!X24 | AC13: ='1. Master scoring '!Y24 | ... AI13: ='1. Master scoring '!AE24 -> 0 | AJ13: ='1. Master scoring '!#REF! -> #REF! | AK13: ='1. Master scoring '!AF24 | AL13: ='1. Master scoring '!AG24
A14: =IF('4. VAS list'!B19="","",'4. VAS list'!B19) | B14: ='4. VAS list'!C19 -> 0 | C14: ='4. VAS list'!G19 -> 0 | D14: ='4. VAS list'!E19 -> 0 | E14: ='4. VAS list'!F19 -> 0 | F14: ='4. VAS list'!G19 -> 0 | G14: ='4. VAS list'!H19 -> 0 | H14: ='4. VAS list'!I19 -> 0 | I14: ='5. Input GTM Strategy '!E24 -> 0 | J14: ='5. Input GTM Strategy '!F24 -> 0 | K14: ='5. Input GTM Strategy '!H24 -> 0 | L14: ='5. Input GTM Strategy '!I24 -> 0 | M14: ='5. Input GTM Strategy '!H24 -> 0 | N14: ='5. Input GTM Strategy '!I24 -> 0 | O14: ='5. Input GTM Strategy '!K24 -> 0 | P14: ='5. Input GTM Strategy '!L24 -> 0 | Q14: ='5. Input GTM Strategy '!M24 -> 0 | R14: ='5. Input GTM Strategy '!N24 -> 0 | S14: ='5. Input GTM Strategy '!R24 -> 0 | T14: ='5. Input GTM Strategy '!S24 -> 0 | U14: ='5. Input GTM Strategy '!U24 -> 0 | V14: ='1. Master scoring '!R25 | W14: ='1. Master scoring '!S25 | X14: ='1. Master scoring '!T25 -> 0 | Y14: ='1. Master scoring '!U25 -> 0 | Z14: ='1. Master scoring '!V25 -> 0 | AA14: ='1. Master scoring '!W25 | AB14: ='1. Master scoring '!X25 | AC14: ='1. Master scoring '!Y25 | ... AI14: ='1. Master scoring '!AE25 -> 0 | AJ14: ='1. Master scoring '!#REF! -> #REF! | AK14: ='1. Master scoring '!AF25 | AL14: ='1. Master scoring '!AG25
A15: =IF('4. VAS list'!B20="","",'4. VAS list'!B20) | B15: ='4. VAS list'!C20 -> 0 | C15: ='4. VAS list'!D20 -> 0 | D15: ='4. VAS list'!E20 -> 0 | E15: ='4. VAS list'!F20 -> 0 | F15: ='4. VAS list'!G20 -> 0 | G15: ='4. VAS list'!H20 -> 0 | H15: ='4. VAS list'!I20 -> 0 | I15: ='5. Input GTM Strategy '!E25 -> 0 | J15: ='5. Input GTM Strategy '!F25 -> 0 | K15: ='5. Input GTM Strategy '!H25 -> 0 | L15: ='5. Input GTM Strategy '!I25 -> 0 | M15: ='5. Input GTM Strategy '!H25 -> 0 | N15: ='5. Input GTM Strategy '!I25 -> 0 | O15: ='5. Input GTM Strategy '!K25 -> 0 | P15: ='5. Input GTM Strategy '!L25 -> 0 | Q15: ='5. Input GTM Strategy '!M25 -> 0 | R15: ='5. Input GTM Strategy '!N25 -> 0 | S15: ='5. Input GTM Strategy '!R25 -> 0 | T15: ='5. Input GTM Strategy '!S25 -> 0 | U15: ='5. Input GTM Strategy '!U25 -> 0 | V15: ='1. Master scoring '!R26 | W15: ='1. Master scoring '!S26 | X15: ='1. Master scoring '!T26 -> 0 | Y15: ='1. Master scoring '!U26 -> 0 | Z15: ='1. Master scoring '!V26 -> 0 | AA15: ='1. Master scoring '!W26 | AB15: ='1. Master scoring '!X26 | AC15: ='1. Master scoring '!Y26 | ... AI15: ='1. Master scoring '!AE26 -> 0 | AJ15: ='1. Master scoring '!#REF! -> #REF! | AK15: ='1. Master scoring '!AF26 | AL15: ='1. Master scoring '!AG26
A16: =IF('4. VAS list'!B21="","",'4. VAS list'!B21) | B16: ='4. VAS list'!C21 -> 0 | C16: ='4. VAS list'!D21 -> 0 | D16: ='4. VAS list'!E21 -> 0 | E16: ='4. VAS list'!F21 -> 0 | F16: ='4. VAS list'!G21 -> 0 | G16: ='4. VAS list'!H21 -> 0 | H16: ='4. VAS list'!I21 -> 0 | I16: ='5. Input GTM Strategy '!E26 -> 0 | J16: ='5. Input GTM Strategy '!F26 -> 0 | K16: ='5. Input GTM Strategy '!H26 -> 0 | L16: ='5. Input GTM Strategy '!I26 -> 0 | M16: ='5. Input GTM Strategy '!H26 -> 0 | N16: ='5. Input GTM Strategy '!I26 -> 0 | O16: ='5. Input GTM Strategy '!K26 -> 0 | P16: ='5. Input GTM Strategy '!L26 -> 0 | Q16: ='5. Input GTM Strategy '!M26 -> 0 | R16: ='5. Input GTM Strategy '!N26 -> 0 | S16: ='5. Input GTM Strategy '!R26 -> 0 | T16: ='5. Input GTM Strategy '!S26 -> 0 | U16: ='5. Input GTM Strategy '!U26 -> 0 | V16: ='1. Master scoring '!R27 | W16: ='1. Master scoring '!S27 | X16: ='1. Master scoring '!T27 -> 0 | Y16: ='1. Master scoring '!U27 -> 0 | Z16: ='1. Master scoring '!V27 -> 0 | AA16: ='1. Master scoring '!W27 | AB16: ='1. Master scoring '!X27 | AC16: ='1. Master scoring '!Y27 | ... AI16: ='1. Master scoring '!AE27 -> 0 | AJ16: ='1. Master scoring '!#REF! -> #REF! | AK16: ='1. Master scoring '!AF27 | AL16: ='1. Master scoring '!AG27
A17: =IF('4. VAS list'!B22="","",'4. VAS list'!B22) | B17: ='4. VAS list'!C22 -> 0 | C17: ='4. VAS list'!D22 -> 0 | D17: ='4. VAS list'!E22 -> 0 | E17: ='4. VAS list'!F22 -> 0 | F17: ='4. VAS list'!G22 -> 0 | G17: ='4. VAS list'!H22 -> 0 | H17: ='4. VAS list'!I22 -> 0 | I17: ='5. Input GTM Strategy '!E27 -> 0 | J17: ='5. Input GTM Strategy '!F27 -> 0 | K17: ='5. Input GTM Strategy '!H27 -> 0 | L17: ='5. Input GTM Strategy '!I27 -> 0 | M17: ='5. Input GTM Strategy '!H27 -> 0 | N17: ='5. Input GTM Strategy '!I27 -> 0 | O17: ='5. Input GTM Strategy '!K27 -> 0 | P17: ='5. Input GTM Strategy '!L27 -> 0 | Q17: ='5. Input GTM Strategy '!M27 -> 0 | R17: ='5. Input GTM Strategy '!N27 -> 0 | S17: ='5. Input GTM Strategy '!R27 -> 0 | T17: ='5. Input GTM Strategy '!S27 -> 0 | U17: ='5. Input GTM Strategy '!U27 -> 0 | V17: ='1. Master scoring '!R28 | W17: ='1. Master scoring '!S28 | X17: ='1. Master scoring '!T28 -> 0 | Y17: ='1. Master scoring '!U28 -> 0 | Z17: ='1. Master scoring '!V28 -> 0 | AA17: ='1. Master scoring '!W28 | AB17: ='1. Master scoring '!X28 | AC17: ='1. Master scoring '!Y28 | ... AI17: ='1. Master scoring '!AE28 -> 0 | AJ17: ='1. Master scoring '!#REF! -> #REF! | AK17: ='1. Master scoring '!AF28 | AL17: ='1. Master scoring '!AG28
A18: =IF('4. VAS list'!B23="","",'4. VAS list'!B23) | B18: ='4. VAS list'!C23 -> 0 | C18: ='4. VAS list'!D23 -> 0 | D18: ='4. VAS list'!E23 -> 0 | E18: ='4. VAS list'!F23 -> 0 | F18: ='4. VAS list'!G23 -> 0 | G18: ='4. VAS list'!H23 -> 0 | H18: ='4. VAS list'!I23 -> 0 | I18: ='5. Input GTM Strategy '!E28 -> 0 | J18: ='5. Input GTM Strategy '!F28 -> 0 | K18: ='5. Input GTM Strategy '!H28 -> 0 | L18: ='5. Input GTM Strategy '!I28 -> 0 | M18: ='5. Input GTM Strategy '!H28 -> 0 | N18: ='5. Input GTM Strategy '!I28 -> 0 | O18: ='5. Input GTM Strategy '!K28 -> 0 | P18: ='5. Input GTM Strategy '!L28 -> 0 | Q18: ='5. Input GTM Strategy '!M28 -> 0 | R18: ='5. Input GTM Strategy '!N28 -> 0 | S18: ='5. Input GTM Strategy '!R28 -> 0 | T18: ='5. Input GTM Strategy '!S28 -> 0 | U18: ='5. Input GTM Strategy '!U28 -> 0 | V18: ='1. Master scoring '!R29 | W18: ='1. Master scoring '!S29 | X18: ='1. Master scoring '!T29 -> 0 | Y18: ='1. Master scoring '!U29 -> 0 | Z18: ='1. Master scoring '!V29 -> 0 | AA18: ='1. Master scoring '!W29 | AB18: ='1. Master scoring '!X29 | AC18: ='1. Master scoring '!Y29 | ... AI18: ='1. Master scoring '!AE29 -> 0 | AJ18: ='1. Master scoring '!#REF! -> #REF! | AK18: ='1. Master scoring '!AF29 | AL18: ='1. Master scoring '!AG29
A19: =IF('4. VAS list'!B24="","",'4. VAS list'!B24) | B19: ='4. VAS list'!C24 -> 0 | C19: ='4. VAS list'!D24 -> 0 | D19: ='4. VAS list'!E24 -> 0 | E19: ='4. VAS list'!F24 -> 0 | F19: ='4. VAS list'!G24 -> 0 | G19: ='4. VAS list'!H24 -> 0 | H19: ='4. VAS list'!I24 -> 0 | I19: ='5. Input GTM Strategy '!E29 -> 0 | J19: ='5. Input GTM Strategy '!F29 -> 0 | K19: ='5. Input GTM Strategy '!H29 -> 0 | L19: ='5. Input GTM Strategy '!I29 -> 0 | M19: ='5. Input GTM Strategy '!H29 -> 0 | N19: ='5. Input GTM Strategy '!I29 -> 0 | O19: ='5. Input GTM Strategy '!K29 -> 0 | P19: ='5. Input GTM Strategy '!L29 -> 0 | Q19: ='5. Input GTM Strategy '!M29 -> 0 | R19: ='5. Input GTM Strategy '!N29 -> 0 | S19: ='5. Input GTM Strategy '!R29 -> 0 | T19: ='5. Input GTM Strategy '!S29 -> 0 | U19: ='5. Input GTM Strategy '!U29 -> 0 | V19: ='1. Master scoring '!R30 | W19: ='1. Master scoring '!S30 | X19: ='1. Master scoring '!T30 -> 0 | Y19: ='1. Master scoring '!U30 -> 0 | Z19: ='1. Master scoring '!V30 -> 0 | AA19: ='1. Master scoring '!W30 | AB19: ='1. Master scoring '!X30 | AC19: ='1. Master scoring '!Y30 | ... AI19: ='1. Master scoring '!AE30 -> 0 | AJ19: ='1. Master scoring '!#REF! -> #REF! | AK19: ='1. Master scoring '!AF30 | AL19: ='1. Master scoring '!AG30
A20: =IF('4. VAS list'!B25="","",'4. VAS list'!B25) | B20: ='4. VAS list'!C25 -> 0 | C20: ='4. VAS list'!D25 -> 0 | D20: ='4. VAS list'!E25 -> 0 | E20: ='4. VAS list'!F25 -> 0 | F20: ='4. VAS list'!G25 -> 0 | G20: ='4. VAS list'!H25 -> 0 | H20: ='4. VAS list'!I25 -> 0 | I20: ='5. Input GTM Strategy '!E30 -> 0 | J20: ='5. Input GTM Strategy '!F30 -> 0 | K20: ='5. Input GTM Strategy '!H30 -> 0 | L20: ='5. Input GTM Strategy '!I30 -> 0 | M20: ='5. Input GTM Strategy '!H30 -> 0 | N20: ='5. Input GTM Strategy '!I30 -> 0 | O20: ='5. Input GTM Strategy '!K30 -> 0 | P20: ='5. Input GTM Strategy '!L30 -> 0 | Q20: ='5. Input GTM Strategy '!M30 -> 0 | R20: ='5. Input GTM Strategy '!N30 -> 0 | S20: ='5. Input GTM Strategy '!R30 -> 0 | T20: ='5. Input GTM Strategy '!S30 -> 0 | U20: ='5. Input GTM Strategy '!U30 -> 0 | V20: ='1. Master scoring '!R31 | W20: ='1. Master scoring '!S31 | X20: ='1. Master scoring '!T31 -> 0 | Y20: ='1. Master scoring '!U31 -> 0 | Z20: ='1. Master scoring '!V31 -> 0 | AA20: ='1. Master scoring '!W31 | AB20: ='1. Master scoring '!X31 | AC20: ='1. Master scoring '!Y31 | ... AI20: ='1. Master scoring '!AE31 -> 0 | AJ20: ='1. Master scoring '!#REF! -> #REF! | AK20: ='1. Master scoring '!AF31 | AL20: ='1. Master scoring '!AG31
A21: =IF('4. VAS list'!B26="","",'4. VAS list'!B26) | B21: ='4. VAS list'!C26 -> 0 | C21: ='4. VAS list'!D26 -> 0 | D21: ='4. VAS list'!E26 -> 0 | E21: ='4. VAS list'!F26 -> 0 | F21: ='4. VAS list'!G26 -> 0 | G21: ='4. VAS list'!H26 -> 0 | H21: ='4. VAS list'!I26 -> 0 | I21: ='5. Input GTM Strategy '!E31 -> 0 | J21: ='5. Input GTM Strategy '!F31 -> 0 | K21: ='5. Input GTM Strategy '!H31 -> 0 | L21: ='5. Input GTM Strategy '!I31 -> 0 | M21: ='5. Input GTM Strategy '!H31 -> 0 | N21: ='5. Input GTM Strategy '!I31 -> 0 | O21: ='5. Input GTM Strategy '!K31 -> 0 | P21: ='5. Input GTM Strategy '!L31 -> 0 | Q21: ='5. Input GTM Strategy '!M31 -> 0 | R21: ='5. Input GTM Strategy '!N31 -> 0 | S21: ='5. Input GTM Strategy '!R31 -> 0 | T21: ='5. Input GTM Strategy '!S31 -> 0 | U21: ='5. Input GTM Strategy '!U31 -> 0 | V21: ='1. Master scoring '!R32 -> 0 | W21: ='1. Master scoring '!S32 -> 0 | X21: ='1. Master scoring '!T32 -> 0 | Y21: ='1. Master scoring '!U32 -> 0 | Z21: ='1. Master scoring '!V32 -> 0 | AA21: ='1. Master scoring '!W32 -> 0 | AB21: ='1. Master scoring '!X32 -> 0 | AC21: ='1. Master scoring '!Y32 -> 0 | ... AI21: ='1. Master scoring '!AE32 -> 0 | AJ21: ='1. Master scoring '!#REF! -> #REF! | AK21: ='1. Master scoring '!AF32 -> 0 | AL21: ='1. Master scoring '!AG32 -> 0
A22: =IF('4. VAS list'!B27="","",'4. VAS list'!B27) | B22: ='4. VAS list'!C27 -> 0 | C22: ='4. VAS list'!D27 -> 0 | D22: ='4. VAS list'!E27 -> 0 | E22: ='4. VAS list'!F27 -> 0 | F22: ='4. VAS list'!G27 -> 0 | G22: ='4. VAS list'!H27 -> 0 | H22: ='4. VAS list'!I27 -> 0 | I22: ='5. Input GTM Strategy '!E32 -> 0 | J22: ='5. Input GTM Strategy '!F32 -> 0 | K22: ='5. Input GTM Strategy '!H32 -> 0 | L22: ='5. Input GTM Strategy '!I32 -> 0 | M22: ='5. Input GTM Strategy '!H32 -> 0 | N22: ='5. Input GTM Strategy '!I32 -> 0 | O22: ='5. Input GTM Strategy '!K32 -> 0 | P22: ='5. Input GTM Strategy '!L32 -> 0 | Q22: ='5. Input GTM Strategy '!M32 -> 0 | R22: ='5. Input GTM Strategy '!N32 -> 0 | S22: ='5. Input GTM Strategy '!R32 -> 0 | T22: ='5. Input GTM Strategy '!S32 -> 0 | U22: ='5. Input GTM Strategy '!U32 -> 0 | V22: ='1. Master scoring '!R33 -> 0 | W22: ='1. Master scoring '!S33 -> 0 | X22: ='1. Master scoring '!T33 -> 0 | Y22: ='1. Master scoring '!U33 -> 0 | Z22: ='1. Master scoring '!V33 -> 0 | AA22: ='1. Master scoring '!W33 -> 0 | AB22: ='1. Master scoring '!X33 -> 0 | AC22: ='1. Master scoring '!Y33 -> 0 | ... AI22: ='1. Master scoring '!AE33 -> 0 | AJ22: ='1. Master scoring '!#REF! -> #REF! | AK22: ='1. Master scoring '!AF33 -> 0 | AL22: ='1. Master scoring '!AG33 -> 0
A23: =IF('4. VAS list'!B28="","",'4. VAS list'!B28) | B23: ='4. VAS list'!C28 -> 0 | C23: ='4. VAS list'!D28 -> 0 | D23: ='4. VAS list'!E28 -> 0 | E23: ='4. VAS list'!F28 -> 0 | F23: ='4. VAS list'!G28 -> 0 | G23: ='4. VAS list'!H28 -> 0 | H23: ='4. VAS list'!I28 -> 0 | I23: ='5. Input GTM Strategy '!E33 -> 0 | J23: ='5. Input GTM Strategy '!F33 -> 0 | K23: ='5. Input GTM Strategy '!H33 -> 0 | L23: ='5. Input GTM Strategy '!I33 -> 0 | M23: ='5. Input GTM Strategy '!H33 -> 0 | N23: ='5. Input GTM Strategy '!I33 -> 0 | O23: ='5. Input GTM Strategy '!K33 -> 0 | P23: ='5. Input GTM Strategy '!L33 -> 0 | Q23: ='5. Input GTM Strategy '!M33 -> 0 | R23: ='5. Input GTM Strategy '!N33 -> 0 | S23: ='5. Input GTM Strategy '!R33 -> 0 | T23: ='5. Input GTM Strategy '!S33 -> 0 | U23: ='5. Input GTM Strategy '!U33 -> 0 | V23: ='1. Master scoring '!R34 -> 0 | W23: ='1. Master scoring '!S34 -> 0 | X23: ='1. Master scoring '!T34 -> 0 | Y23: ='1. Master scoring '!U34 -> 0 | Z23: ='1. Master scoring '!V34 -> 0 | AA23: ='1. Master scoring '!W34 -> 0 | AB23: ='1. Master scoring '!X34 -> 0 | AC23: ='1. Master scoring '!Y34 -> 0 | ... AI23: ='1. Master scoring '!AE34 -> 0 | AJ23: ='1. Master scoring '!#REF! -> #REF! | AK23: ='1. Master scoring '!AF34 -> 0 | AL23: ='1. Master scoring '!AG34 -> 0
A24: =IF('4. VAS list'!B29="","",'4. VAS list'!B29) | B24: ='4. VAS list'!C29 -> 0 | C24: ='4. VAS list'!D29 -> 0 | D24: ='4. VAS list'!E29 -> 0 | E24: ='4. VAS list'!F29 -> 0 | F24: ='4. VAS list'!G29 -> 0 | G24: ='4. VAS list'!H29 -> 0 | H24: ='4. VAS list'!I29 -> 0 | I24: ='5. Input GTM Strategy '!E34 -> 0 | J24: ='5. Input GTM Strategy '!F34 -> 0 | K24: ='5. Input GTM Strategy '!H34 -> 0 | L24: ='5. Input GTM Strategy '!I34 -> 0 | M24: ='5. Input GTM Strategy '!H34 -> 0 | N24: ='5. Input GTM Strategy '!I34 -> 0 | O24: ='5. Input GTM Strategy '!K34 -> 0 | P24: ='5. Input GTM Strategy '!L34 -> 0 | Q24: ='5. Input GTM Strategy '!M34 -> 0 | R24: ='5. Input GTM Strategy '!N34 -> 0 | S24: ='5. Input GTM Strategy '!R34 -> 0 | T24: ='5. Input GTM Strategy '!S34 -> 0 | U24: ='5. Input GTM Strategy '!U34 -> 0 | V24: ='1. Master scoring '!R35 -> 0 | W24: ='1. Master scoring '!S35 -> 0 | X24: ='1. Master scoring '!T35 -> 0 | Y24: ='1. Master scoring '!U35 -> 0 | Z24: ='1. Master scoring '!V35 -> 0 | AA24: ='1. Master scoring '!W35 -> 0 | AB24: ='1. Master scoring '!X35 -> 0 | AC24: ='1. Master scoring '!Y35 -> 0 | ... AI24: ='1. Master scoring '!AE35 -> 0 | AJ24: ='1. Master scoring '!#REF! -> #REF! | AK24: ='1. Master scoring '!AF35 -> 0 | AL24: ='1. Master scoring '!AG35 -> 0
A25: =IF('4. VAS list'!B30="","",'4. VAS list'!B30) | B25: ='4. VAS list'!C30 -> 0 | C25: ='4. VAS list'!D30 -> 0 | D25: ='4. VAS list'!E30 -> 0 | E25: ='4. VAS list'!F30 -> 0 | F25: ='4. VAS list'!G30 -> 0 | G25: ='4. VAS list'!H30 -> 0 | H25: ='4. VAS list'!I30 -> 0 | I25: ='5. Input GTM Strategy '!E35 -> 0 | J25: ='5. Input GTM Strategy '!F35 -> 0 | K25: ='5. Input GTM Strategy '!H35 -> 0 | L25: ='5. Input GTM Strategy '!I35 -> 0 | M25: ='5. Input GTM Strategy '!H35 -> 0 | N25: ='5. Input GTM Strategy '!I35 -> 0 | O25: ='5. Input GTM Strategy '!K35 -> 0 | P25: ='5. Input GTM Strategy '!L35 -> 0 | Q25: ='5. Input GTM Strategy '!M35 -> 0 | R25: ='5. Input GTM Strategy '!N35 -> 0 | S25: ='5. Input GTM Strategy '!R35 -> 0 | T25: ='5. Input GTM Strategy '!S35 -> 0 | U25: ='5. Input GTM Strategy '!U35 -> 0 | V25: ='1. Master scoring '!R36 -> 0 | W25: ='1. Master scoring '!S36 -> 0 | X25: ='1. Master scoring '!T36 -> 0 | Y25: ='1. Master scoring '!U36 -> 0 | Z25: ='1. Master scoring '!V36 -> 0 | AA25: ='1. Master scoring '!W36 -> 0 | AB25: ='1. Master scoring '!X36 -> 0 | AC25: ='1. Master scoring '!Y36 -> 0 | ... AI25: ='1. Master scoring '!AE36 -> 0 | AJ25: ='1. Master scoring '!#REF! -> #REF! | AK25: ='1. Master scoring '!AF36 -> 0 | AL25: ='1. Master scoring '!AG36 -> 0
A26: =IF('4. VAS list'!B31="","",'4. VAS list'!B31) | B26: ='4. VAS list'!C31 -> 0 | C26: ='4. VAS list'!D31 -> 0 | D26: ='4. VAS list'!E31 -> 0 | E26: ='4. VAS list'!F31 -> 0 | F26: ='4. VAS list'!G31 -> 0 | G26: ='4. VAS list'!H31 -> 0 | H26: ='4. VAS list'!I31 -> 0 | I26: ='5. Input GTM Strategy '!E36 -> 0 | J26: ='5. Input GTM Strategy '!F36 -> 0 | K26: ='5. Input GTM Strategy '!H36 -> 0 | L26: ='5. Input GTM Strategy '!I36 -> 0 | M26: ='5. Input GTM Strategy '!H36 -> 0 | N26: ='5. Input GTM Strategy '!I36 -> 0 | O26: ='5. Input GTM Strategy '!K36 -> 0 | P26: ='5. Input GTM Strategy '!L36 -> 0 | Q26: ='5. Input GTM Strategy '!M36 -> 0 | R26: ='5. Input GTM Strategy '!N36 -> 0 | S26: ='5. Input GTM Strategy '!R36 -> 0 | T26: ='5. Input GTM Strategy '!S36 -> 0 | U26: ='5. Input GTM Strategy '!U36 -> 0 | V26: ='1. Master scoring '!R37 -> 0 | W26: ='1. Master scoring '!S37 -> 0 | X26: ='1. Master scoring '!T37 -> 0 | Y26: ='1. Master scoring '!U37 -> 0 | Z26: ='1. Master scoring '!V37 -> 0 | AA26: ='1. Master scoring '!W37 -> 0 | AB26: ='1. Master scoring '!X37 -> 0 | AC26: ='1. Master scoring '!Y37 -> 0 | ... AI26: ='1. Master scoring '!AE37 -> 0 | AJ26: ='1. Master scoring '!#REF! -> #REF! | AK26: ='1. Master scoring '!AF37 -> 0 | AL26: ='1. Master scoring '!AG37 -> 0
... A35: =IF('4. VAS list'!B40="","",'4. VAS list'!B40) | B35: ='4. VAS list'!C40 -> 0 | C35: ='4. VAS list'!D40 -> 0 | D35: ='4. VAS list'!E40 -> 0 | E35: ='4. VAS list'!F40 -> 0 | F35: ='4. VAS list'!G40 -> 0 | G35: ='4. VAS list'!H40 -> 0 | H35: ='4. VAS list'!I40 -> 0 | I35: ='5. Input GTM Strategy '!E45 -> 0 | J35: ='5. Input GTM Strategy '!F45 -> 0 | K35: ='5. Input GTM Strategy '!H45 -> 0 | L35: ='5. Input GTM Strategy '!I45 -> 0 | M35: ='5. Input GTM Strategy '!H45 -> 0 | N35: ='5. Input GTM Strategy '!I45 -> 0 | O35: ='5. Input GTM Strategy '!K45 -> 0 | P35: ='5. Input GTM Strategy '!L45 -> 0 | Q35: ='5. Input GTM Strategy '!M45 -> 0 | R35: ='5. Input GTM Strategy '!N45 -> 0 | S35: ='5. Input GTM Strategy '!R45 -> 0 | T35: ='5. Input GTM Strategy '!S45 -> 0 | U35: ='5. Input GTM Strategy '!U45 -> 0 | V35: ='1. Master scoring '!R46 -> 0 | W35: ='1. Master scoring '!S46 -> 0 | X35: ='1. Master scoring '!T46 -> 0 | Y35: ='1. Master scoring '!U46 -> 0 | Z35: ='1. Master scoring '!V46 -> 0 | AA35: ='1. Master scoring '!W46 -> 0 | AB35: ='1. Master scoring '!X46 -> 0 | AC35: ='1. Master scoring '!Y46 -> 0 | ... AI35: ='1. Master scoring '!AE46 -> 0 | AJ35: ='1. Master scoring '!#REF! -> #REF! | AK35: ='1. Master scoring '!AF46 -> 0 | AL35: ='1. Master scoring '!AG46 -> 0

Sheet 1. Master scoring 
B2: Master scoring
B3: Detailed visualization of all added VAS
C7: MANUAL INPUT | I7: MANUAL/AUTOMATED INPUT. | O7: AUTOMATED.
C8: OVERVIEW | I8: Priority | O8: Score | R8: Scoring criteria (av.)
O9: Scoring | R9: Grow core Business Margin | X9: Commercial Viability | Z9: Customer Desirability | AC9: Execution | AH9: Price VS Costs | AL9: EXTRA INFORMATION | AN9: Resources
C10: VAS | D10: Description | E10: LOB | F10: Category | J10: Core Business | K10: Commercial Viability | L10: Execution | M10: Customer Desirability | O10: Overall Score | P10: Rank | R10: Core Business Sales | S10: % Multiproduct | T10: Customer base | U10: Customer acquisition costs | V10: Claim costs | W10: TOTAL | X10: Business Risk | Y10: TOTAL | Z10: Perceived Value | AA10: Potential Reach | AB10: TOTAL | AC10: Improve NPS | AD10: Retention | AE10: Increase customers' interactions (TP) | AF10: Regulation | AG10: TOTAL | AH10: Insurance Price | AI10: Insurance Cost | AJ10: TOTAL | AL10: Additional notes | AN10: Are there relevant research materials?
O11: =IFERROR(AVERAGEIF($C14:$C130,"<>",O14:O130),"") -> 3.8598485 | P11: - | R11: =IFERROR(AVERAGEIF($C14:$C130,"<>",R14:R130),"") -> 4.7333333 | S11: =IFERROR(AVERAGEIF($C14:$C130,"<>",S14:S130),"") | T11: =IFERROR(AVERAGEIF($C14:$C130,"<>",T14:T130),"") -> 2.7333333 | U11: =IFERROR(AVERAGEIF($C14:$C130,"<>",U14:U130),"") -> 4.4666667 | V11: =IFERROR(AVERAGEIF($C14:$C130,"<>",V14:V130),"") -> 2.8666667 | W11: =IFERROR(AVERAGEIF($C14:$C130,"<>",W14:W130),"") -> 0.925 | X11: =IFERROR(AVERAGEIF($C14:$C130,"<>",X14:X130),"") -> 3.8 | Y11: =IFERROR(AVERAGEIF($C14:$C130,"<>",Y14:Y130),"") -> 3.8 | ... AJ11: =IFERROR(AVERAGEIF($C14:$C130,"<>",AJ14:AJ130),"")
C12: What is the name of the VAS? | D12: Brief description of VAS | E12: Which strategic pillar does this VAS fall under? | F12: If 'Net new', can the feature be grouped into a broader area or pain point? | L12: Does this feature meet the requirements for its opportunity type? See 'Scoring criteria' for minimum requirement details | O12: Overall score. | P12: Rank | R12: How are VAS' revenues contributing to the company performance? | S12: How much this VAS improve sales of other products/services? | T12: How many customers are acquired thanks to this VAS? | U12: How much the VAS contribute to reduce the cost of acquisition of a single customer? | V12: How much the VAS contribute to reduce the cost of single claim? | W12: Overall Business Margin score | X12: How expose are we to this VAS considering: reputation, financial and customer relation? | Y12: Overall Commercial Viability score | Z12: How much value would this feature deliver to customers? | AA12: What is the total number of customers (i.e. market size) we could realistically offer this feature to? | AB12: Overall Customer Desirability score | AC12: What is the customers' satisfaction (NPS) related to the service? | AD12: Percentage of customer that are actively using the service. | AE12: How often the customer interact with the VAS? | AF12: How complex or restrictive is the regulatory environment for this VAS? | AG12: Overall Execution Feasibility score | AH12: Price of the insurance for the customer | AI12: Cost of the insurance for the company | AJ12: Overall Execution Feasibility score | AL12: What was the outcome of review? Are there agreed next steps to be aware of? | AN12: Materials #1 | AO12: Materials #2 | AP12: Materials #3
C13: Automated. | D13: Automated. | E13: Automated. | F13: Automated. | J13: Automated. | K13: Automated. | L13: Automated. | M13: Automated. | O13: Automated. | P13: Automated. | R13: 5: Very high impact 4: High impact 3: Some impact 2: Low impact 1: No impact | S13: 5: Very high impact 4: High impact 3: Some impact 2: Low impact 1: No impact | T13: 5: Large Amount 4: A lot 3: Some 2: Few 1: No client | U13: 5: High Contribution 4: Moderate contribution 3: Medium contribution 2: Low contribution 1: Very low contribution | V13: 5: High Contribution 4: Moderate contribution 3: Medium contribution 2: Low contribution 1: Very low contribution | W13: Automated. | X13: 5: Very Low Risk 4: Low Risk 3: Medium Risk 2: Moderate Risk 1: High Risk | Y13: Automated. | Z13: 5: Very high value 4: High value 3: Some value 2: Low value 1: No value | AA13: 5: Mass market 4: Large reach 3: Solid reach 2: Niche segment 1: Very niche segment | AB13: Automated. | AC13: 5: from 9 to 10 4: from 7 to 8 3: from 6 to 5 2: from 3 to 4 1: from 1 to 2 | AD13: 5: More than X% 4: Between X% and X% 3 Between X% and X% 2: Between X% and X% 1: Less than X% | AE13: 5: more than six times a year 4: six times a year 3: four a year 2: twice a year 1: once a year | AF13: 5: No red tape 4: Low regulation 3: Some regulation 2: Highly regulated 1: Very highly regulated | AG13: Automated. | AH13: Value | AI13: Value | AJ13: Overall Execution Feasibility score | AL13: Manual | AN13: Manual | AO13: Manual | AP13: Manual
C14: ='4. VAS list'!B8 -> Telemedicine | D14: =IF('4. VAS list'!C8="","",'4. VAS list'!C8) -> Cover the costs of private healthcare, from diagnosis to treatment | E14: =IF('4. VAS list'!G8="","",'4. VAS list'!G8) -> DigitalAccessAndProtection​ | F14: =IF('4. VAS list'!H8="","",'4. VAS list'!H8) -> Practical guides / Prevention information​ | J14: {=_xlfn.IFNA(_xlfn.IFS('4. VAS list'!$I8='1. Master scoring '!$J$10,1,'4. VAS list'!$J8='1. Master scoring '!$J$10,2,'4. VAS list'!$K8='1. Master scoring '!$J$10,3,'4. VAS list'!$L8='1. Master scoring '!$J$10,4),"Completare")} -> 1 | K14: {=_xlfn.IFNA(_xlfn.IFS('4. VAS list'!$I8='1. Master scoring '!$K$10,1,'4. VAS list'!$J8='1. Master scoring '!$K$10,2,'4. VAS list'!$K8='1. Master scoring '!$K$10,3,'4. VAS list'!$L8='1. Master scoring '!$K$10,4),"Completare")} -> 2 | L14: {=_xlfn.IFNA(_xlfn.IFS('4. VAS list'!$I8='1. Master scoring '!$L$10,1,'4. VAS list'!$J8='1. Master scoring '!$L$10,2,'4. VAS list'!$K8='1. Master scoring '!$L$10,3,'4. VAS list'!$L8='1. Master scoring '!$L$10,4),"Completare")} -> 3 | M14: {=_xlfn.IFNA(_xlfn.IFS('4. VAS list'!$I8='1. Master scoring '!$M$10,1,'4. VAS list'!$J8='1. Master scoring '!$M$10,2,'4. VAS list'!$K8='1. Master scoring '!$M$10,3,'4. VAS list'!$L8='1. Master scoring '!$M$10,4),"Completare")} -> 4 | O14: =IFERROR(AVERAGE(R14:W14,X14:X14,Z14:Z14,AC14:AF14),"") -> 4.2443182 | P14: =IFERROR(RANK(O14,$O$14:$O$128,0)+COUNTIF($O$14:O14,#REF!)," ") -> 1 | R14: =IFERROR(AVERAGE('4a. Scorer 1'!F13,'4b. Scorer 2'!F13,'4c. Scorer 3'!F13)," ") -> 5 | S14: =IFERROR(AVERAGE('4a. Scorer 1'!G13,'4b. Scorer 2'!G13,'4c. Scorer 3'!G13)," ") | T14: =IFERROR(AVERAGE('4a. Scorer 1'!H13,'4b. Scorer 2'!H13,'4c. Scorer 3'!H13)," ") -> 4 | U14: =IFERROR(AVERAGE('4a. Scorer 1'!I13,'4b. Scorer 2'!I13,'4c. Scorer 3'!I13)," ") -> 5 | V14: =IFERROR(AVERAGE('4a. Scorer 1'!J13,'4b. Scorer 2'!J13,'4c. Scorer 3'!J13)," ") -> 2.3333333 | W14: =IFERROR(AVERAGE(R14:V14)*(J14/MAX(J14:M14)),"") -> 1.0208333 | X14: =IFERROR(AVERAGE('4a. Scorer 1'!L13,'4b. Scorer 2'!L13,'4c. Scorer 3'!L13)," ") -> 4.3333333 | Y14: =IFERROR(AVERAGE(X14:X14)*(M14/MAX(J14:M14)),"") -> 4.3333333 | Z14: =IFERROR(AVERAGE('4a. Scorer 1'!N13,'4b. Scorer 2'!N13,'4c. Scorer 3'!N13)," ") -> 5 | AA14: =IFERROR(AVERAGE('4a. Scorer 1'!O13,'4b. Scorer 2'!O13,'4c. Scorer 3'!O13)," ") -> 5 | AB14: =IFERROR(AVERAGE(Z14:Z14)*(L14/MAX(J14:M14)),"") -> 3.75 | AC14: =IFERROR(AVERAGE('4a. Scorer 1'!Q13,'4b. Scorer 2'!Q13,'4c. Scorer 3'!Q13)," ") -> 5 | AD14: =IFERROR(AVERAGE('4a. Scorer 1'!R13,'4b. Scorer 2'!R13,'4c. Scorer 3'!R13)," ") -> 5 | AE14: =IFERROR(AVERAGE('4a. Scorer 1'!S13,'4b. Scorer 2'!S13,'4c. Scorer 3'!S13)," ") -> 5 | AF14: =IFERROR(AVERAGE('4a. Scorer 1'!T13,'4b. Scorer 2'!T13,'4c. Scorer 3'!T13)," ") -> 5 | AG14: =IFERROR(AVERAGE(AC14:AF14)*(K14/MAX(J14:M14)),"") -> 2.5 | AH14: =IFERROR(AVERAGE('4a. Scorer 1'!V13,'4b. Scorer 2'!V13,'4c. Scorer 3'!V13)," ") -> 2.6666667 | AI14: =IFERROR(AVERAGE('4a. Scorer 1'!W13,'4b. Scorer 2'!W13,'4c. Scorer 3'!W13)," ") -> 4 | AL14: Deprioritised based on lack of clear customer need/potential partners
C15: ='4. VAS list'!B9 -> ID Theft | D15: =IF('4. VAS list'!C9="","",'4. VAS list'!C9) -> Cover the costs you might incur from being defrauded | E15: =IF('4. VAS list'!G9="","",'4. VAS list'!G9) -> Health​ | F15: =IF('4. VAS list'!H9="","",'4. VAS list'!H9) -> Medical & health specialist services​ | J15: {=_xlfn.IFNA(_xlfn.IFS('4. VAS list'!$I9='1. Master scoring '!$J$10,1,'4. VAS list'!$J9='1. Master scoring '!$J$10,2,'4. VAS list'!$K9='1. Master scoring '!$J$10,3,'4. VAS list'!$L9='1. Master scoring '!$J$10,4),"Completare")} -> 1 | K15: {=_xlfn.IFNA(_xlfn.IFS('4. VAS list'!$I9='1. Master scoring '!$K$10,1,'4. VAS list'!$J9='1. Master scoring '!$K$10,2,'4. VAS list'!$K9='1. Master scoring '!$K$10,3,'4. VAS list'!$L9='1. Master scoring '!$K$10,4),"Completare")} -> 2 | L15: {=_xlfn.IFNA(_xlfn.IFS('4. VAS list'!$I9='1. Master scoring '!$L$10,1,'4. VAS list'!$J9='1. Master scoring '!$L$10,2,'4. VAS list'!$K9='1. Master scoring '!$L$10,3,'4. VAS list'!$L9='1. Master scoring '!$L$10,4),"Completare")} -> 3 | M15: {=_xlfn.IFNA(_xlfn.IFS('4. VAS list'!$I9='1. Master scoring '!$M$10,1,'4. VAS list'!$J9='1. Master scoring '!$M$10,2,'4. VAS list'!$K9='1. Master scoring '!$M$10,3,'4. VAS list'!$L9='1. Master scoring '!$M$10,4),"Completare")} -> 4 | O15: =IFERROR(AVERAGE(R15:W15,X15:X15,Z15:Z15,AC15:AF15),"") -> 3.9299242 | P15: =IFERROR(RANK(O15,$O$14:$O$128,0)+COUNTIF($O$14:O15,#REF!)," ") -> 2 | R15: =IFERROR(AVERAGE('4a. Scorer 1'!F14,'4b. Scorer 2'!F14,'4c. Scorer 3'!F14)," ") -> 5 | S15: =IFERROR(AVERAGE('4a. Scorer 1'!G14,'4b. Scorer 2'!G14,'4c. Scorer 3'!G14)," ") | T15: =IFERROR(AVERAGE('4a. Scorer 1'!H14,'4b. Scorer 2'!H14,'4c. Scorer 3'!H14)," ") -> 2 | U15: =IFERROR(AVERAGE('4a. Scorer 1'!I14,'4b. Scorer 2'!I14,'4c. Scorer 3'!I14)," ") -> 5 | V15: =IFERROR(AVERAGE('4a. Scorer 1'!J14,'4b. Scorer 2'!J14,'4c. Scorer 3'!J14)," ") -> 2.3333333 | W15: =IFERROR(AVERAGE(R15:V15)*(J15/MAX(J15:M15)),"") -> 0.89583333 | X15: =IFERROR(AVERAGE('4a. Scorer 1'!L14,'4b. Scorer 2'!L14,'4c. Scorer 3'!L14)," ") -> 4 | Y15: =IFERROR(AVERAGE(X15:X15)*(M15/MAX(J15:M15)),"") -> 4 | Z15: =IFERROR(AVERAGE('4a. Scorer 1'!N14,'4b. Scorer 2'!N14,'4c. Scorer 3'!N14)," ") -> 4.6666667 | AA15: =IFERROR(AVERAGE('4a. Scorer 1'!O14,'4b. Scorer 2'!O14,'4c. Scorer 3'!O14)," ") -> 4 | AB15: =IFERROR(AVERAGE(Z15:Z15)*(L15/MAX(J15:M15)),"") -> 3.5 | AC15: =IFERROR(AVERAGE('4a. Scorer 1'!Q14,'4b. Scorer 2'!Q14,'4c. Scorer 3'!Q14)," ") -> 5 | AD15: =IFERROR(AVERAGE('4a. Scorer 1'!R14,'4b. Scorer 2'!R14,'4c. Scorer 3'!R14)," ") -> 5 | AE15: =IFERROR(AVERAGE('4a. Scorer 1'!S14,'4b. Scorer 2'!S14,'4c. Scorer 3'!S14)," ") -> 5 | AF15: =IFERROR(AVERAGE('4a. Scorer 1'!T14,'4b. Scorer 2'!T14,'4c. Scorer 3'!T14)," ") -> 4.3333333 | AG15: =IFERROR(AVERAGE(AC15:AF15)*(K15/MAX(J15:M15)),"") -> 2.4166667 | AH15: =IFERROR(AVERAGE('4a. Scorer 1'!V14,'4b. Scorer 2'!V14,'4c. Scorer 3'!V14)," ") -> 1 | AI15: =IFERROR(AVERAGE('4a. Scorer 1'!W14,'4b. Scorer 2'!W14,'4c. Scorer 3'!W14)," ") -> 3 | AL15: Progressed for business casing
C16: ='4. VAS list'!B10 -> Vehicle Geolocation | D16: =IF('4. VAS list'!C10="","",'4. VAS list'!C10) -> Install an approved GPS tracking device and reduce vehicle insurance premium | E16: =IF('4. VAS list'!G10="","",'4. VAS list'!G10) -> Mobility​ | F16: =IF('4. VAS list'!H10="","",'4. VAS list'!H10) -> Mobility assistance (bikes, fines help)​ | J16: {=_xlfn.IFNA(_xlfn.IFS('4. VAS list'!$I10='1. Master scoring '!$J$10,1,'4. VAS list'!$J10='1. Master scoring '!$J$10,2,'4. VAS list'!$K10='1. Master scoring '!$J$10,3,'4. VAS list'!$L10='1. Master scoring '!$J$10,4),"Completare")} -> 1 | K16: {=_xlfn.IFNA(_xlfn.IFS('4. VAS list'!$I10='1. Master scoring '!$K$10,1,'4. VAS list'!$J10='1. Master scoring '!$K$10,2,'4. VAS list'!$K10='1. Master scoring '!$K$10,3,'4. VAS list'!$L10='1. Master scoring '!$K$10,4),"Completare")} -> 2 | L16: {=_xlfn.IFNA(_xlfn.IFS('4. VAS list'!$I10='1. Master scoring '!$L$10,1,'4. VAS list'!$J10='1. Master scoring '!$L$10,2,'4. VAS list'!$K10='1. Master scoring '!$L$10,3,'4. VAS list'!$L10='1. Master scoring '!$L$10,4),"Completare")} -> 3 | M16: {=_xlfn.IFNA(_xlfn.IFS('4. VAS list'!$I10='1. Master scoring '!$M$10,1,'4. VAS list'!$J10='1. Master scoring '!$M$10,2,'4. VAS list'!$K10='1. Master scoring '!$M$10,3,'4. VAS list'!$L10='1. Master scoring '!$M$10,4),"Completare")} -> 4 | O16: =IFERROR(AVERAGE(R16:W16,X16:X16,Z16:Z16,AC16:AF16),"") -> 3.8731061 | P16: =IFERROR(RANK(O16,$O$14:$O$128,0)+COUNTIF($O$14:O16,#REF!)," ") -> 3 | R16: =IFERROR(AVERAGE('4a. Scorer 1'!F15,'4b. Scorer 2'!F15,'4c. Scorer 3'!F15)," ") -> 5 | S16: =IFERROR(AVERAGE('4a. Scorer 1'!G15,'4b. Scorer 2'!G15,'4c. Scorer 3'!G15)," ") | T16: =IFERROR(AVERAGE('4a. Scorer 1'!H15,'4b. Scorer 2'!H15,'4c. Scorer 3'!H15)," ") -> 2.6666667 | U16: =IFERROR(AVERAGE('4a. Scorer 1'!I15,'4b. Scorer 2'!I15,'4c. Scorer 3'!I15)," ") -> 4.3333333 | V16: =IFERROR(AVERAGE('4a. Scorer 1'!J15,'4b. Scorer 2'!J15,'4c. Scorer 3'!J15)," ") -> 3 | W16: =IFERROR(AVERAGE(R16:V16)*(J16/MAX(J16:M16)),"") -> 0.9375 | X16: =IFERROR(AVERAGE('4a. Scorer 1'!L15,'4b. Scorer 2'!L15,'4c. Scorer 3'!L15)," ") -> 3.6666667 | Y16: =IFERROR(AVERAGE(X16:X16)*(M16/MAX(J16:M16)),"") -> 3.6666667 | Z16: =IFERROR(AVERAGE('4a. Scorer 1'!N15,'4b. Scorer 2'!N15,'4c. Scorer 3'!N15)," ") -> 4.6666667 | AA16: =IFERROR(AVERAGE('4a. Scorer 1'!O15,'4b. Scorer 2'!O15,'4c. Scorer 3'!O15)," ") -> 4.6666667 | AB16: =IFERROR(AVERAGE(Z16:Z16)*(L16/MAX(J16:M16)),"") -> 3.5 | AC16: =IFERROR(AVERAGE('4a. Scorer 1'!Q15,'4b. Scorer 2'!Q15,'4c. Scorer 3'!Q15)," ") -> 4 | AD16: =IFERROR(AVERAGE('4a. Scorer 1'!R15,'4b. Scorer 2'!R15,'4c. Scorer 3'!R15)," ") -> 4.6666667 | AE16: =IFERROR(AVERAGE('4a. Scorer 1'!S15,'4b. Scorer 2'!S15,'4c. Scorer 3'!S15)," ") -> 4.6666667 | AF16: =IFERROR(AVERAGE('4a. Scorer 1'!T15,'4b. Scorer 2'!T15,'4c. Scorer 3'!T15)," ") -> 5 | AG16: =IFERROR(AVERAGE(AC16:AF16)*(K16/MAX(J16:M16)),"") -> 2.2916667 | AH16: =IFERROR(AVERAGE('4a. Scorer 1'!V15,'4b. Scorer 2'!V15,'4c. Scorer 3'!V15)," ") -> 1 | AI16: =IFERROR(AVERAGE('4a. Scorer 1'!W15,'4b. Scorer 2'!W15,'4c. Scorer 3'!W15)," ") -> 3 | AL16: Previously assessed; depriortised based on financial risk/lack of clear upside
C17: ='4. VAS list'!B11 -> Pet Care | D17: =IF('4. VAS list'!C11="","",'4. VAS list'!C11) -> Cover the cost of veterinary fees for illnesses or injuries | E17: =IF('4. VAS list'!G11="","",'4. VAS list'!G11) -> HomeAndFamily​ | F17: =IF('4. VAS list'!H11="","",'4. VAS list'!H11) -> Pet care​ | J17: {=_xlfn.IFNA(_xlfn.IFS('4. VAS list'!$I11='1. Master scoring '!$J$10,1,'4. VAS list'!$J11='1. Master scoring '!$J$10,2,'4. VAS list'!$K11='1. Master scoring '!$J$10,3,'4. VAS list'!$L11='1. Master scoring '!$J$10,4),"")} -> 1 | K17: {=_xlfn.IFNA(_xlfn.IFS('4. VAS list'!$I11='1. Master scoring '!$K$10,1,'4. VAS list'!$J11='1. Master scoring '!$K$10,2,'4. VAS list'!$K11='1. Master scoring '!$K$10,3,'4. VAS list'!$L11='1. Master scoring '!$K$10,4),"Completare")} -> 2 | L17: {=_xlfn.IFNA(_xlfn.IFS('4. VAS list'!$I11='1. Master scoring '!$L$10,1,'4. VAS list'!$J11='1. Master scoring '!$L$10,2,'4. VAS list'!$K11='1. Master scoring '!$L$10,3,'4. VAS list'!$L11='1. Master scoring '!$L$10,4),"Completare")} -> 3 | M17: {=_xlfn.IFNA(_xlfn.IFS('4. VAS list'!$I11='1. Master scoring '!$M$10,1,'4. VAS list'!$J11='1. Master scoring '!$M$10,2,'4. VAS list'!$K11='1. Master scoring '!$M$10,3,'4. VAS list'!$L11='1. Master scoring '!$M$10,4),"Completare")} -> 4 | O17: =IFERROR(AVERAGE(R17:W17,X17:X17,Z17:Z17,AC17:AF17),"") -> 3.7784091 | P17: =IFERROR(RANK(O17,$O$14:$O$128,0)+COUNTIF($O$14:O17,#REF!)," ") -> 4 | R17: =IFERROR(AVERAGE('4a. Scorer 1'!F16,'4b. Scorer 2'!F16,'4c. Scorer 3'!F16)," ") -> 4.6666667 | S17: =IFERROR(AVERAGE('4a. Scorer 1'!G16,'4b. Scorer 2'!G16,'4c. Scorer 3'!G16)," ") | T17: =IFERROR(AVERAGE('4a. Scorer 1'!H16,'4b. Scorer 2'!H16,'4c. Scorer 3'!H16)," ") -> 2.3333333 | U17: =IFERROR(AVERAGE('4a. Scorer 1'!I16,'4b. Scorer 2'!I16,'4c. Scorer 3'!I16)," ") -> 4.3333333 | V17: =IFERROR(AVERAGE('4a. Scorer 1'!J16,'4b. Scorer 2'!J16,'4c. Scorer 3'!J16)," ") -> 3 | W17: =IFERROR(AVERAGE(R17:V17)*(J17/MAX(J17:M17)),"") -> 0.89583333 | X17: =IFERROR(AVERAGE('4a. Scorer 1'!L16,'4b. Scorer 2'!L16,'4c. Scorer 3'!L16)," ") -> 3.3333333 | Y17: =IFERROR(AVERAGE(X17:X17)*(M17/MAX(J17:M17)),"") -> 3.3333333 | Z17: =IFERROR(AVERAGE('4a. Scorer 1'!N16,'4b. Scorer 2'!N16,'4c. Scorer 3'!N16)," ") -> 4 | AA17: =IFERROR(AVERAGE('4a. Scorer 1'!O16,'4b. Scorer 2'!O16,'4c. Scorer 3'!O16)," ") -> 4.3333333 | AB17: =IFERROR(AVERAGE(Z17:Z17)*(L17/MAX(J17:M17)),"") -> 3 | AC17: =IFERROR(AVERAGE('4a. Scorer 1'!Q16,'4b. Scorer 2'!Q16,'4c. Scorer 3'!Q16)," ") -> 5 | AD17: =IFERROR(AVERAGE('4a. Scorer 1'!R16,'4b. Scorer 2'!R16,'4c. Scorer 3'!R16)," ") -> 5 | AE17: =IFERROR(AVERAGE('4a. Scorer 1'!S16,'4b. Scorer 2'!S16,'4c. Scorer 3'!S16)," ") -> 4.6666667 | AF17: =IFERROR(AVERAGE('4a. Scorer 1'!T16,'4b. Scorer 2'!T16,'4c. Scorer 3'!T16)," ") -> 4.3333333 | AG17: =IFERROR(AVERAGE(AC17:AF17)*(K17/MAX(J17:M17)),"") -> 2.375 | AH17: =IFERROR(AVERAGE('4a. Scorer 1'!V16,'4b. Scorer 2'!V16,'4c. Scorer 3'!V16)," ") -> 1 | AI17: =IFERROR(AVERAGE('4a. Scorer 1'!W16,'4b. Scorer 2'!W16,'4c. Scorer 3'!W16)," ") -> 3
C18: ='4. VAS list'!B12 -> Road Assistance | D18: =IF('4. VAS list'!C12="","",'4. VAS list'!C12) -> Lorem ipsum | E18: =IF('4. VAS list'!G12="","",'4. VAS list'!G12) -> Mobility​ | F18: =IF('4. VAS list'!H12="","",'4. VAS list'!H12) -> Emergency response​ | J18: {=_xlfn.IFNA(_xlfn.IFS('4. VAS list'!$I12='1. Master scoring '!$J$10,1,'4. VAS list'!$J12='1. Master scoring '!$J$10,2,'4. VAS list'!$K12='1. Master scoring '!$J$10,3,'4. VAS list'!$L12='1. Master scoring '!$J$10,4),"")} -> 1 | K18: {=_xlfn.IFNA(_xlfn.IFS('4. VAS list'!$I12='1. Master scoring '!$K$10,1,'4. VAS list'!$J12='1. Master scoring '!$K$10,2,'4. VAS list'!$K12='1. Master scoring '!$K$10,3,'4. VAS list'!$L12='1. Master scoring '!$K$10,4),"")} -> 2 | L18: {=_xlfn.IFNA(_xlfn.IFS('4. VAS list'!$I12='1. Master scoring '!$L$10,1,'4. VAS list'!$J12='1. Master scoring '!$L$10,2,'4. VAS list'!$K12='1. Master scoring '!$L$10,3,'4. VAS list'!$L12='1. Master scoring '!$L$10,4),"")} -> 3 | M18: {=_xlfn.IFNA(_xlfn.IFS('4. VAS list'!$I12='1. Master scoring '!$M$10,1,'4. VAS list'!$J12='1. Master scoring '!$M$10,2,'4. VAS list'!$K12='1. Master scoring '!$M$10,3,'4. VAS list'!$L12='1. Master scoring '!$M$10,4),"")} -> 4 | O18: =IFERROR(AVERAGE(R18:W18,X18:X18,Z18:Z18,AC18:AF18),"") -> 3.4734848 | P18: =IFERROR(RANK(O18,$O$14:$O$128,0)+COUNTIF($O$14:O18,#REF!)," ") -> 5 | R18: =IFERROR(AVERAGE('4a. Scorer 1'!F17,'4b. Scorer 2'!F17,'4c. Scorer 3'!F17)," ") -> 4 | S18: =IFERROR(AVERAGE('4a. Scorer 1'!G17,'4b. Scorer 2'!G17,'4c. Scorer 3'!G17)," ") | T18: =IFERROR(AVERAGE('4a. Scorer 1'!H17,'4b. Scorer 2'!H17,'4c. Scorer 3'!H17)," ") -> 2.6666667 | U18: =IFERROR(AVERAGE('4a. Scorer 1'!I17,'4b. Scorer 2'!I17,'4c. Scorer 3'!I17)," ") -> 3.6666667 | V18: =IFERROR(AVERAGE('4a. Scorer 1'!J17,'4b. Scorer 2'!J17,'4c. Scorer 3'!J17)," ") -> 3.6666667 | W18: =IFERROR(AVERAGE(R18:V18)*(J18/MAX(J18:M18)),"") -> 0.875 | X18: =IFERROR(AVERAGE('4a. Scorer 1'!L17,'4b. Scorer 2'!L17,'4c. Scorer 3'!L17)," ") -> 3.6666667 | Y18: =IFERROR(AVERAGE(X18:X18)*(M18/MAX(J18:M18)),"") -> 3.6666667 | Z18: =IFERROR(AVERAGE('4a. Scorer 1'!N17,'4b. Scorer 2'!N17,'4c. Scorer 3'!N17)," ") -> 4.6666667 | AA18: =IFERROR(AVERAGE('4a. Scorer 1'!O17,'4b. Scorer 2'!O17,'4c. Scorer 3'!O17)," ") -> 3.6666667 | AB18: =IFERROR(AVERAGE(Z18:Z18)*(L18/MAX(J18:M18)),"") -> 3.5 | AC18: =IFERROR(AVERAGE('4a. Scorer 1'!Q17,'4b. Scorer 2'!Q17,'4c. Scorer 3'!Q17)," ") -> 4 | AD18: =IFERROR(AVERAGE('4a. Scorer 1'!R17,'4b. Scorer 2'!R17,'4c. Scorer 3'!R17)," ") -> 3.3333333 | AE18: =IFERROR(AVERAGE('4a. Scorer 1'!S17,'4b. Scorer 2'!S17,'4c. Scorer 3'!S17)," ") -> 4.3333333 | AF18: =IFERROR(AVERAGE('4a. Scorer 1'!T17,'4b. Scorer 2'!T17,'4c. Scorer 3'!T17)," ") -> 3.3333333 | AG18: =IFERROR(AVERAGE(AC18:AF18)*(K18/MAX(J18:M18)),"") -> 1.875 | AH18: =IFERROR(AVERAGE('4a. Scorer 1'!V17,'4b. Scorer 2'!V17,'4c. Scorer 3'!V17)," ") -> 1 | AI18: =IFERROR(AVERAGE('4a. Scorer 1'!W17,'4b. Scorer 2'!W17,'4c. Scorer 3'!W17)," ") -> 3
C19: =IF(ISBLANK('4. VAS list'!B13),"",'4. VAS list'!B13) | E19: =IF('4. VAS list'!G13="","",'4. VAS list'!G13) | F19: =IF('4. VAS list'!H13="","",'4. VAS list'!H13) | J19: {=_xlfn.IFNA(_xlfn.IFS('4. VAS list'!$I13='1. Master scoring '!$J$10,1,'4. VAS list'!$J13='1. Master scoring '!$J$10,2,'4. VAS list'!$K13='1. Master scoring '!$J$10,3,'4. VAS list'!$L13='1. Master scoring '!$J$10,4),"")} | K19: {=_xlfn.IFNA(_xlfn.IFS('4. VAS list'!$I13='1. Master scoring '!$K$10,1,'4. VAS list'!$J13='1. Master scoring '!$K$10,2,'4. VAS list'!$K13='1. Master scoring '!$K$10,3,'4. VAS list'!$L13='1. Master scoring '!$K$10,4),"")} | L19: {=_xlfn.IFNA(_xlfn.IFS('4. VAS list'!$I13='1. Master scoring '!$L$10,1,'4. VAS list'!$J13='1. Master scoring '!$L$10,2,'4. VAS list'!$K13='1. Master scoring '!$L$10,3,'4. VAS list'!$L13='1. Master scoring '!$L$10,4),"")} | M19: {=_xlfn.IFNA(_xlfn.IFS('4. VAS list'!$I13='1. Master scoring '!$M$10,1,'4. VAS list'!$J13='1. Master scoring '!$M$10,2,'4. VAS list'!$K13='1. Master scoring '!$M$10,3,'4. VAS list'!$L13='1. Master scoring '!$M$10,4),"")} | O19: =IFERROR(AVERAGE(R19:W19,X19:X19,Z19:Z19,AC19:AF19),"") | P19: =IFERROR(RANK(O19,$O$14:$O$128,0)+COUNTIF($O$14:O19,#REF!)," ") | R19: =IFERROR(AVERAGE('4a. Scorer 1'!F18,'4b. Scorer 2'!F18,'4c. Scorer 3'!F18)," ") | S19: =IFERROR(AVERAGE('4a. Scorer 1'!G18,'4b. Scorer 2'!G18,'4c. Scorer 3'!G18)," ") | T19: =IFERROR(AVERAGE('4a. Scorer 1'!H18,'4b. Scorer 2'!H18,'4c. Scorer 3'!H18)," ") | U19: =IFERROR(AVERAGE('4a. Scorer 1'!I18,'4b. Scorer 2'!I18,'4c. Scorer 3'!I18)," ") | V19: =IFERROR(AVERAGE('4a. Scorer 1'!J18,'4b. Scorer 2'!J18,'4c. Scorer 3'!J18)," ") | W19: =IFERROR(AVERAGE(R19:V19)*(J19/MAX(J19:M19)),"") | X19: =IFERROR(AVERAGE('4a. Scorer 1'!L18,'4b. Scorer 2'!L18,'4c. Scorer 3'!L18)," ") | Y19: =IFERROR(AVERAGE(X19:X19)*(M19/MAX(J19:M19)),"") | Z19: =IFERROR(AVERAGE('4a. Scorer 1'!N18,'4b. Scorer 2'!N18,'4c. Scorer 3'!N18)," ") | AA19: =IFERROR(AVERAGE('4a. Scorer 1'!O18,'4b. Scorer 2'!O18,'4c. Scorer 3'!O18)," ") | AC19: =IFERROR(AVERAGE('4a. Scorer 1'!Q18,'4b. Scorer 2'!Q18,'4c. Scorer 3'!Q18)," ") | AD19: =IFERROR(AVERAGE('4a. Scorer 1'!R18,'4b. Scorer 2'!R18,'4c. Scorer 3'!R18)," ") | AE19: =IFERROR(AVERAGE('4a. Scorer 1'!S18,'4b. Scorer 2'!S18,'4c. Scorer 3'!S18)," ") | AF19: =IFERROR(AVERAGE('4a. Scorer 1'!T18,'4b. Scorer 2'!T18,'4c. Scorer 3'!T18)," ") | AG19: =IFERROR(AVERAGE(AC19:AF19)*(K19/MAX(J19:M19)),"") | AH19: =IFERROR(AVERAGE('4a. Scorer 1'!V18,'4b. Scorer 2'!V18,'4c. Scorer 3'!V18)," ") | AI19: =IFERROR(AVERAGE('4a. Scorer 1'!W18,'4b. Scorer 2'!W18,'4c. Scorer 3'!W18)," ")
